[2025-03-26T10:32:44.355+0000] {local_task_job_runner.py:123} INFO - ::group::Pre task execution logs
[2025-03-26T10:32:44.363+0000] {taskinstance.py:2614} INFO - Dependencies all met for dep_context=non-requeueable deps ti=<TaskInstance: google_dag.extract manual__2025-03-26T10:19:00.055352+00:00 [queued]>
[2025-03-26T10:32:44.367+0000] {taskinstance.py:2614} INFO - Dependencies all met for dep_context=requeueable deps ti=<TaskInstance: google_dag.extract manual__2025-03-26T10:19:00.055352+00:00 [queued]>
[2025-03-26T10:32:44.367+0000] {taskinstance.py:2867} INFO - Starting attempt 2 of 2
[2025-03-26T10:32:44.373+0000] {taskinstance.py:2890} INFO - Executing <Task(PythonOperator): extract> on 2025-03-26 10:19:00.055352+00:00
[2025-03-26T10:32:44.377+0000] {warnings.py:112} WARNING - /home/***/.local/lib/python3.12/site-packages/***/task/task_runner/standard_task_runner.py:70: DeprecationWarning: This process (pid=240) is multi-threaded, use of fork() may lead to deadlocks in the child.
  pid = os.fork()

[2025-03-26T10:32:44.378+0000] {standard_task_runner.py:72} INFO - Started process 241 to run task
[2025-03-26T10:32:44.379+0000] {standard_task_runner.py:104} INFO - Running: ['***', 'tasks', 'run', 'google_dag', 'extract', 'manual__2025-03-26T10:19:00.055352+00:00', '--job-id', '356', '--raw', '--subdir', 'DAGS_FOLDER/google_dag.py', '--cfg-path', '/tmp/tmpamf798gr']
[2025-03-26T10:32:44.380+0000] {standard_task_runner.py:105} INFO - Job 356: Subtask extract
[2025-03-26T10:32:44.405+0000] {task_command.py:467} INFO - Running <TaskInstance: google_dag.extract manual__2025-03-26T10:19:00.055352+00:00 [running]> on host 5faecdb8342b
[2025-03-26T10:32:44.442+0000] {taskinstance.py:3134} INFO - Exporting env vars: AIRFLOW_CTX_DAG_OWNER='***' AIRFLOW_CTX_DAG_ID='google_dag' AIRFLOW_CTX_TASK_ID='extract' AIRFLOW_CTX_EXECUTION_DATE='2025-03-26T10:19:00.055352+00:00' AIRFLOW_CTX_TRY_NUMBER='2' AIRFLOW_CTX_DAG_RUN_ID='manual__2025-03-26T10:19:00.055352+00:00'
[2025-03-26T10:32:44.443+0000] {logging_mixin.py:190} INFO - Task instance is in running state
[2025-03-26T10:32:44.443+0000] {logging_mixin.py:190} INFO -  Previous state of the Task instance: queued
[2025-03-26T10:32:44.444+0000] {logging_mixin.py:190} INFO - Current task name:extract state:running start_date:2025-03-26 10:32:44.364032+00:00
[2025-03-26T10:32:44.444+0000] {logging_mixin.py:190} INFO - Dag name:google_dag and current dag run status:running
[2025-03-26T10:32:44.444+0000] {taskinstance.py:732} INFO - ::endgroup::
[2025-03-26T10:39:19.807+0000] {taskinstance.py:3313} ERROR - Task failed with exception
Traceback (most recent call last):
  File "/home/airflow/.local/lib/python3.12/site-packages/requests/adapters.py", line 667, in send
    resp = conn.urlopen(
           ^^^^^^^^^^^^^
  File "/home/airflow/.local/lib/python3.12/site-packages/urllib3/connectionpool.py", line 889, in urlopen
    return self.urlopen(
           ^^^^^^^^^^^^^
  File "/home/airflow/.local/lib/python3.12/site-packages/urllib3/connectionpool.py", line 889, in urlopen
    return self.urlopen(
           ^^^^^^^^^^^^^
  File "/home/airflow/.local/lib/python3.12/site-packages/urllib3/connectionpool.py", line 889, in urlopen
    return self.urlopen(
           ^^^^^^^^^^^^^
  [Previous line repeated 2 more times]
  File "/home/airflow/.local/lib/python3.12/site-packages/urllib3/connectionpool.py", line 879, in urlopen
    retries = retries.increment(method, url, response=response, _pool=self)
              ^^^^^^^^^^^^^^^^^^^^^^^^^^^^^^^^^^^^^^^^^^^^^^^^^^^^^^^^^^^^^
  File "/home/airflow/.local/lib/python3.12/site-packages/urllib3/util/retry.py", line 592, in increment
    raise MaxRetryError(_pool, url, error or ResponseError(cause))
urllib3.exceptions.MaxRetryError: HTTPSConnectionPool(host='trends.google.com', port=443): Max retries exceeded with url: /trends/api/widgetdata/multiline?req=%7B%22time%22%3A+%222025-03-25+2025-03-25%22%2C+%22resolution%22%3A+%22DAY%22%2C+%22locale%22%3A+%22ko%22%2C+%22comparisonItem%22%3A+%5B%7B%22geo%22%3A+%7B%22country%22%3A+%22KR%22%7D%2C+%22complexKeywordsRestriction%22%3A+%7B%22keyword%22%3A+%5B%7B%22type%22%3A+%22BROAD%22%2C+%22value%22%3A+%22%5Cuae40%5Cubb38%5Cuc218%22%7D%5D%7D%7D%5D%2C+%22requestOptions%22%3A+%7B%22property%22%3A+%22%22%2C+%22backend%22%3A+%22IZG%22%2C+%22category%22%3A+0%7D%2C+%22userConfig%22%3A+%7B%22userType%22%3A+%22USER_TYPE_SCRAPER%22%7D%7D&token=APP6_UEAAAAAZ-UqP4-rl56IXX9JdUIypz973oVS2E21&tz=540 (Caused by ResponseError('too many 429 error responses'))

During handling of the above exception, another exception occurred:

Traceback (most recent call last):
  File "/home/airflow/.local/lib/python3.12/site-packages/airflow/models/taskinstance.py", line 768, in _execute_task
    result = _execute_callable(context=context, **execute_callable_kwargs)
             ^^^^^^^^^^^^^^^^^^^^^^^^^^^^^^^^^^^^^^^^^^^^^^^^^^^^^^^^^^^^^
  File "/home/airflow/.local/lib/python3.12/site-packages/airflow/models/taskinstance.py", line 734, in _execute_callable
    return ExecutionCallableRunner(
           ^^^^^^^^^^^^^^^^^^^^^^^^
  File "/home/airflow/.local/lib/python3.12/site-packages/airflow/utils/operator_helpers.py", line 252, in run
    return self.func(*args, **kwargs)
           ^^^^^^^^^^^^^^^^^^^^^^^^^^
  File "/home/airflow/.local/lib/python3.12/site-packages/airflow/models/baseoperator.py", line 424, in wrapper
    return func(self, *args, **kwargs)
           ^^^^^^^^^^^^^^^^^^^^^^^^^^^
  File "/home/airflow/.local/lib/python3.12/site-packages/airflow/operators/python.py", line 238, in execute
    return_value = self.execute_callable()
                   ^^^^^^^^^^^^^^^^^^^^^^^
  File "/home/airflow/.local/lib/python3.12/site-packages/airflow/operators/python.py", line 256, in execute_callable
    return runner.run(*self.op_args, **self.op_kwargs)
           ^^^^^^^^^^^^^^^^^^^^^^^^^^^^^^^^^^^^^^^^^^^
  File "/home/airflow/.local/lib/python3.12/site-packages/airflow/utils/operator_helpers.py", line 252, in run
    return self.func(*args, **kwargs)
           ^^^^^^^^^^^^^^^^^^^^^^^^^^
  File "/opt/airflow/plugins/scripts/extract/google_extract.py", line 48, in extract_google_data
    df = pytrends.interest_over_time()
         ^^^^^^^^^^^^^^^^^^^^^^^^^^^^^
  File "/home/airflow/.local/lib/python3.12/site-packages/pytrends/request.py", line 232, in interest_over_time
    req_json = self._get_data(
               ^^^^^^^^^^^^^^^
  File "/home/airflow/.local/lib/python3.12/site-packages/pytrends/request.py", line 140, in _get_data
    response = s.get(url, timeout=self.timeout, cookies=self.cookies,
               ^^^^^^^^^^^^^^^^^^^^^^^^^^^^^^^^^^^^^^^^^^^^^^^^^^^^^^
  File "/home/airflow/.local/lib/python3.12/site-packages/requests/sessions.py", line 602, in get
    return self.request("GET", url, **kwargs)
           ^^^^^^^^^^^^^^^^^^^^^^^^^^^^^^^^^^
  File "/home/airflow/.local/lib/python3.12/site-packages/requests/sessions.py", line 589, in request
    resp = self.send(prep, **send_kwargs)
           ^^^^^^^^^^^^^^^^^^^^^^^^^^^^^^
  File "/home/airflow/.local/lib/python3.12/site-packages/requests/sessions.py", line 703, in send
    r = adapter.send(request, **kwargs)
        ^^^^^^^^^^^^^^^^^^^^^^^^^^^^^^^
  File "/home/airflow/.local/lib/python3.12/site-packages/requests/adapters.py", line 691, in send
    raise RetryError(e, request=request)
requests.exceptions.RetryError: HTTPSConnectionPool(host='trends.google.com', port=443): Max retries exceeded with url: /trends/api/widgetdata/multiline?req=%7B%22time%22%3A+%222025-03-25+2025-03-25%22%2C+%22resolution%22%3A+%22DAY%22%2C+%22locale%22%3A+%22ko%22%2C+%22comparisonItem%22%3A+%5B%7B%22geo%22%3A+%7B%22country%22%3A+%22KR%22%7D%2C+%22complexKeywordsRestriction%22%3A+%7B%22keyword%22%3A+%5B%7B%22type%22%3A+%22BROAD%22%2C+%22value%22%3A+%22%5Cuae40%5Cubb38%5Cuc218%22%7D%5D%7D%7D%5D%2C+%22requestOptions%22%3A+%7B%22property%22%3A+%22%22%2C+%22backend%22%3A+%22IZG%22%2C+%22category%22%3A+0%7D%2C+%22userConfig%22%3A+%7B%22userType%22%3A+%22USER_TYPE_SCRAPER%22%7D%7D&token=APP6_UEAAAAAZ-UqP4-rl56IXX9JdUIypz973oVS2E21&tz=540 (Caused by ResponseError('too many 429 error responses'))
[2025-03-26T10:39:19.830+0000] {logging_mixin.py:190} INFO - Task instance in failure state
[2025-03-26T10:39:19.830+0000] {logging_mixin.py:190} INFO - Task start:2025-03-26 10:32:44.364032+00:00 end:2025-03-26 10:39:19.828872+00:00 duration:395.46484
[2025-03-26T10:39:19.831+0000] {logging_mixin.py:190} INFO - Task:<Task(PythonOperator): extract> dag:<DAG: google_dag> dagrun:<DagRun google_dag @ 2025-03-26 10:19:00.055352+00:00: manual__2025-03-26T10:19:00.055352+00:00, state:running, queued_at: 2025-03-26 10:19:00.063488+00:00. externally triggered: True>
[2025-03-26T10:39:19.831+0000] {logging_mixin.py:190} INFO - Failure caused by HTTPSConnectionPool(host='trends.google.com', port=443): Max retries exceeded with url: /trends/api/widgetdata/multiline?req=%7B%22time%22%3A+%222025-03-25+2025-03-25%22%2C+%22resolution%22%3A+%22DAY%22%2C+%22locale%22%3A+%22ko%22%2C+%22comparisonItem%22%3A+%5B%7B%22geo%22%3A+%7B%22country%22%3A+%22KR%22%7D%2C+%22complexKeywordsRestriction%22%3A+%7B%22keyword%22%3A+%5B%7B%22type%22%3A+%22BROAD%22%2C+%22value%22%3A+%22%5Cuae40%5Cubb38%5Cuc218%22%7D%5D%7D%7D%5D%2C+%22requestOptions%22%3A+%7B%22property%22%3A+%22%22%2C+%22backend%22%3A+%22IZG%22%2C+%22category%22%3A+0%7D%2C+%22userConfig%22%3A+%7B%22userType%22%3A+%22USER_TYPE_SCRAPER%22%7D%7D&token=APP6_UEAAAAAZ-UqP4-rl56IXX9JdUIypz973oVS2E21&tz=540 (Caused by ResponseError('too many 429 error responses'))
[2025-03-26T10:39:19.831+0000] {taskinstance.py:1226} INFO - Marking task as FAILED. dag_id=google_dag, task_id=extract, run_id=manual__2025-03-26T10:19:00.055352+00:00, execution_date=20250326T101900, start_date=20250326T103244, end_date=20250326T103919
[2025-03-26T10:39:19.854+0000] {taskinstance.py:341} INFO - ::group::Post task execution logs
[2025-03-26T10:39:19.854+0000] {standard_task_runner.py:124} ERROR - Failed to execute job 356 for task extract (HTTPSConnectionPool(host='trends.google.com', port=443): Max retries exceeded with url: /trends/api/widgetdata/multiline?req=%7B%22time%22%3A+%222025-03-25+2025-03-25%22%2C+%22resolution%22%3A+%22DAY%22%2C+%22locale%22%3A+%22ko%22%2C+%22comparisonItem%22%3A+%5B%7B%22geo%22%3A+%7B%22country%22%3A+%22KR%22%7D%2C+%22complexKeywordsRestriction%22%3A+%7B%22keyword%22%3A+%5B%7B%22type%22%3A+%22BROAD%22%2C+%22value%22%3A+%22%5Cuae40%5Cubb38%5Cuc218%22%7D%5D%7D%7D%5D%2C+%22requestOptions%22%3A+%7B%22property%22%3A+%22%22%2C+%22backend%22%3A+%22IZG%22%2C+%22category%22%3A+0%7D%2C+%22userConfig%22%3A+%7B%22userType%22%3A+%22USER_TYPE_SCRAPER%22%7D%7D&token=APP6_UEAAAAAZ-UqP4-rl56IXX9JdUIypz973oVS2E21&tz=540 (Caused by ResponseError('too many 429 error responses')); 241)
Traceback (most recent call last):
  File "/home/airflow/.local/lib/python3.12/site-packages/requests/adapters.py", line 667, in send
    resp = conn.urlopen(
           ^^^^^^^^^^^^^
  File "/home/airflow/.local/lib/python3.12/site-packages/urllib3/connectionpool.py", line 889, in urlopen
    return self.urlopen(
           ^^^^^^^^^^^^^
  File "/home/airflow/.local/lib/python3.12/site-packages/urllib3/connectionpool.py", line 889, in urlopen
    return self.urlopen(
           ^^^^^^^^^^^^^
  File "/home/airflow/.local/lib/python3.12/site-packages/urllib3/connectionpool.py", line 889, in urlopen
    return self.urlopen(
           ^^^^^^^^^^^^^
  [Previous line repeated 2 more times]
  File "/home/airflow/.local/lib/python3.12/site-packages/urllib3/connectionpool.py", line 879, in urlopen
    retries = retries.increment(method, url, response=response, _pool=self)
              ^^^^^^^^^^^^^^^^^^^^^^^^^^^^^^^^^^^^^^^^^^^^^^^^^^^^^^^^^^^^^
  File "/home/airflow/.local/lib/python3.12/site-packages/urllib3/util/retry.py", line 592, in increment
    raise MaxRetryError(_pool, url, error or ResponseError(cause))
urllib3.exceptions.MaxRetryError: HTTPSConnectionPool(host='trends.google.com', port=443): Max retries exceeded with url: /trends/api/widgetdata/multiline?req=%7B%22time%22%3A+%222025-03-25+2025-03-25%22%2C+%22resolution%22%3A+%22DAY%22%2C+%22locale%22%3A+%22ko%22%2C+%22comparisonItem%22%3A+%5B%7B%22geo%22%3A+%7B%22country%22%3A+%22KR%22%7D%2C+%22complexKeywordsRestriction%22%3A+%7B%22keyword%22%3A+%5B%7B%22type%22%3A+%22BROAD%22%2C+%22value%22%3A+%22%5Cuae40%5Cubb38%5Cuc218%22%7D%5D%7D%7D%5D%2C+%22requestOptions%22%3A+%7B%22property%22%3A+%22%22%2C+%22backend%22%3A+%22IZG%22%2C+%22category%22%3A+0%7D%2C+%22userConfig%22%3A+%7B%22userType%22%3A+%22USER_TYPE_SCRAPER%22%7D%7D&token=APP6_UEAAAAAZ-UqP4-rl56IXX9JdUIypz973oVS2E21&tz=540 (Caused by ResponseError('too many 429 error responses'))

During handling of the above exception, another exception occurred:

Traceback (most recent call last):
  File "/home/airflow/.local/lib/python3.12/site-packages/airflow/task/task_runner/standard_task_runner.py", line 117, in _start_by_fork
    ret = args.func(args, dag=self.dag)
          ^^^^^^^^^^^^^^^^^^^^^^^^^^^^^
  File "/home/airflow/.local/lib/python3.12/site-packages/airflow/cli/cli_config.py", line 49, in command
    return func(*args, **kwargs)
           ^^^^^^^^^^^^^^^^^^^^^
  File "/home/airflow/.local/lib/python3.12/site-packages/airflow/utils/cli.py", line 116, in wrapper
    return f(*args, **kwargs)
           ^^^^^^^^^^^^^^^^^^
  File "/home/airflow/.local/lib/python3.12/site-packages/airflow/cli/commands/task_command.py", line 483, in task_run
    task_return_code = _run_task_by_selected_method(args, _dag, ti)
                       ^^^^^^^^^^^^^^^^^^^^^^^^^^^^^^^^^^^^^^^^^^^^
  File "/home/airflow/.local/lib/python3.12/site-packages/airflow/cli/commands/task_command.py", line 256, in _run_task_by_selected_method
    return _run_raw_task(args, ti)
           ^^^^^^^^^^^^^^^^^^^^^^^
  File "/home/airflow/.local/lib/python3.12/site-packages/airflow/cli/commands/task_command.py", line 341, in _run_raw_task
    return ti._run_raw_task(
           ^^^^^^^^^^^^^^^^^
  File "/home/airflow/.local/lib/python3.12/site-packages/airflow/utils/session.py", line 97, in wrapper
    return func(*args, session=session, **kwargs)
           ^^^^^^^^^^^^^^^^^^^^^^^^^^^^^^^^^^^^^^
  File "/home/airflow/.local/lib/python3.12/site-packages/airflow/models/taskinstance.py", line 3006, in _run_raw_task
    return _run_raw_task(
           ^^^^^^^^^^^^^^
  File "/home/airflow/.local/lib/python3.12/site-packages/airflow/models/taskinstance.py", line 274, in _run_raw_task
    TaskInstance._execute_task_with_callbacks(
  File "/home/airflow/.local/lib/python3.12/site-packages/airflow/models/taskinstance.py", line 3161, in _execute_task_with_callbacks
    result = self._execute_task(context, task_orig)
             ^^^^^^^^^^^^^^^^^^^^^^^^^^^^^^^^^^^^^^
  File "/home/airflow/.local/lib/python3.12/site-packages/airflow/models/taskinstance.py", line 3185, in _execute_task
    return _execute_task(self, context, task_orig)
           ^^^^^^^^^^^^^^^^^^^^^^^^^^^^^^^^^^^^^^^
  File "/home/airflow/.local/lib/python3.12/site-packages/airflow/models/taskinstance.py", line 768, in _execute_task
    result = _execute_callable(context=context, **execute_callable_kwargs)
             ^^^^^^^^^^^^^^^^^^^^^^^^^^^^^^^^^^^^^^^^^^^^^^^^^^^^^^^^^^^^^
  File "/home/airflow/.local/lib/python3.12/site-packages/airflow/models/taskinstance.py", line 734, in _execute_callable
    return ExecutionCallableRunner(
           ^^^^^^^^^^^^^^^^^^^^^^^^
  File "/home/airflow/.local/lib/python3.12/site-packages/airflow/utils/operator_helpers.py", line 252, in run
    return self.func(*args, **kwargs)
           ^^^^^^^^^^^^^^^^^^^^^^^^^^
  File "/home/airflow/.local/lib/python3.12/site-packages/airflow/models/baseoperator.py", line 424, in wrapper
    return func(self, *args, **kwargs)
           ^^^^^^^^^^^^^^^^^^^^^^^^^^^
  File "/home/airflow/.local/lib/python3.12/site-packages/airflow/operators/python.py", line 238, in execute
    return_value = self.execute_callable()
                   ^^^^^^^^^^^^^^^^^^^^^^^
  File "/home/airflow/.local/lib/python3.12/site-packages/airflow/operators/python.py", line 256, in execute_callable
    return runner.run(*self.op_args, **self.op_kwargs)
           ^^^^^^^^^^^^^^^^^^^^^^^^^^^^^^^^^^^^^^^^^^^
  File "/home/airflow/.local/lib/python3.12/site-packages/airflow/utils/operator_helpers.py", line 252, in run
    return self.func(*args, **kwargs)
           ^^^^^^^^^^^^^^^^^^^^^^^^^^
  File "/opt/airflow/plugins/scripts/extract/google_extract.py", line 48, in extract_google_data
    df = pytrends.interest_over_time()
         ^^^^^^^^^^^^^^^^^^^^^^^^^^^^^
  File "/home/airflow/.local/lib/python3.12/site-packages/pytrends/request.py", line 232, in interest_over_time
    req_json = self._get_data(
               ^^^^^^^^^^^^^^^
  File "/home/airflow/.local/lib/python3.12/site-packages/pytrends/request.py", line 140, in _get_data
    response = s.get(url, timeout=self.timeout, cookies=self.cookies,
               ^^^^^^^^^^^^^^^^^^^^^^^^^^^^^^^^^^^^^^^^^^^^^^^^^^^^^^
  File "/home/airflow/.local/lib/python3.12/site-packages/requests/sessions.py", line 602, in get
    return self.request("GET", url, **kwargs)
           ^^^^^^^^^^^^^^^^^^^^^^^^^^^^^^^^^^
  File "/home/airflow/.local/lib/python3.12/site-packages/requests/sessions.py", line 589, in request
    resp = self.send(prep, **send_kwargs)
           ^^^^^^^^^^^^^^^^^^^^^^^^^^^^^^
  File "/home/airflow/.local/lib/python3.12/site-packages/requests/sessions.py", line 703, in send
    r = adapter.send(request, **kwargs)
        ^^^^^^^^^^^^^^^^^^^^^^^^^^^^^^^
  File "/home/airflow/.local/lib/python3.12/site-packages/requests/adapters.py", line 691, in send
    raise RetryError(e, request=request)
requests.exceptions.RetryError: HTTPSConnectionPool(host='trends.google.com', port=443): Max retries exceeded with url: /trends/api/widgetdata/multiline?req=%7B%22time%22%3A+%222025-03-25+2025-03-25%22%2C+%22resolution%22%3A+%22DAY%22%2C+%22locale%22%3A+%22ko%22%2C+%22comparisonItem%22%3A+%5B%7B%22geo%22%3A+%7B%22country%22%3A+%22KR%22%7D%2C+%22complexKeywordsRestriction%22%3A+%7B%22keyword%22%3A+%5B%7B%22type%22%3A+%22BROAD%22%2C+%22value%22%3A+%22%5Cuae40%5Cubb38%5Cuc218%22%7D%5D%7D%7D%5D%2C+%22requestOptions%22%3A+%7B%22property%22%3A+%22%22%2C+%22backend%22%3A+%22IZG%22%2C+%22category%22%3A+0%7D%2C+%22userConfig%22%3A+%7B%22userType%22%3A+%22USER_TYPE_SCRAPER%22%7D%7D&token=APP6_UEAAAAAZ-UqP4-rl56IXX9JdUIypz973oVS2E21&tz=540 (Caused by ResponseError('too many 429 error responses'))
[2025-03-26T10:39:19.869+0000] {local_task_job_runner.py:266} INFO - Task exited with return code 1
[2025-03-26T10:39:19.879+0000] {taskinstance.py:3901} INFO - 0 downstream tasks scheduled from follow-on schedule check
[2025-03-26T10:39:19.880+0000] {local_task_job_runner.py:245} INFO - ::endgroup::
