[2025-03-16T05:31:12.181+0000] {local_task_job_runner.py:123} INFO - ::group::Pre task execution logs
[2025-03-16T05:31:12.186+0000] {taskinstance.py:2614} INFO - Dependencies all met for dep_context=non-requeueable deps ti=<TaskInstance: upload_to_gsheets.upload_data_to_gsheets manual__2025-03-16T05:31:10.648351+00:00 [queued]>
[2025-03-16T05:31:12.188+0000] {taskinstance.py:2614} INFO - Dependencies all met for dep_context=requeueable deps ti=<TaskInstance: upload_to_gsheets.upload_data_to_gsheets manual__2025-03-16T05:31:10.648351+00:00 [queued]>
[2025-03-16T05:31:12.188+0000] {taskinstance.py:2867} INFO - Starting attempt 1 of 2
[2025-03-16T05:31:12.192+0000] {taskinstance.py:2890} INFO - Executing <Task(PythonOperator): upload_data_to_gsheets> on 2025-03-16 05:31:10.648351+00:00
[2025-03-16T05:31:12.196+0000] {warnings.py:112} WARNING - /home/***/.local/lib/python3.12/site-packages/***/task/task_runner/standard_task_runner.py:70: DeprecationWarning: This process (pid=115) is multi-threaded, use of fork() may lead to deadlocks in the child.
  pid = os.fork()

[2025-03-16T05:31:12.196+0000] {standard_task_runner.py:72} INFO - Started process 116 to run task
[2025-03-16T05:31:12.197+0000] {standard_task_runner.py:104} INFO - Running: ['***', 'tasks', 'run', 'upload_to_gsheets', 'upload_data_to_gsheets', 'manual__2025-03-16T05:31:10.648351+00:00', '--job-id', '260', '--raw', '--subdir', 'DAGS_FOLDER/gsheet_dag.py', '--cfg-path', '/tmp/tmpp_cuvyhd']
[2025-03-16T05:31:12.197+0000] {standard_task_runner.py:105} INFO - Job 260: Subtask upload_data_to_gsheets
[2025-03-16T05:31:12.220+0000] {task_command.py:467} INFO - Running <TaskInstance: upload_to_gsheets.upload_data_to_gsheets manual__2025-03-16T05:31:10.648351+00:00 [running]> on host 276bdf340b6f
[2025-03-16T05:31:12.247+0000] {taskinstance.py:3134} INFO - Exporting env vars: AIRFLOW_CTX_DAG_OWNER='***' AIRFLOW_CTX_DAG_ID='upload_to_gsheets' AIRFLOW_CTX_TASK_ID='upload_data_to_gsheets' AIRFLOW_CTX_EXECUTION_DATE='2025-03-16T05:31:10.648351+00:00' AIRFLOW_CTX_TRY_NUMBER='1' AIRFLOW_CTX_DAG_RUN_ID='manual__2025-03-16T05:31:10.648351+00:00'
[2025-03-16T05:31:12.248+0000] {logging_mixin.py:190} INFO - Task instance is in running state
[2025-03-16T05:31:12.248+0000] {logging_mixin.py:190} INFO -  Previous state of the Task instance: queued
[2025-03-16T05:31:12.248+0000] {logging_mixin.py:190} INFO - Current task name:upload_data_to_gsheets state:running start_date:2025-03-16 05:31:12.186418+00:00
[2025-03-16T05:31:12.248+0000] {logging_mixin.py:190} INFO - Dag name:upload_to_gsheets and current dag run status:running
[2025-03-16T05:31:12.248+0000] {taskinstance.py:732} INFO - ::endgroup::
[2025-03-16T05:31:13.179+0000] {taskinstance.py:3313} ERROR - Task failed with exception
Traceback (most recent call last):
  File "/home/airflow/.local/lib/python3.12/site-packages/airflow/models/taskinstance.py", line 768, in _execute_task
    result = _execute_callable(context=context, **execute_callable_kwargs)
             ^^^^^^^^^^^^^^^^^^^^^^^^^^^^^^^^^^^^^^^^^^^^^^^^^^^^^^^^^^^^^
  File "/home/airflow/.local/lib/python3.12/site-packages/airflow/models/taskinstance.py", line 734, in _execute_callable
    return ExecutionCallableRunner(
           ^^^^^^^^^^^^^^^^^^^^^^^^
  File "/home/airflow/.local/lib/python3.12/site-packages/airflow/utils/operator_helpers.py", line 252, in run
    return self.func(*args, **kwargs)
           ^^^^^^^^^^^^^^^^^^^^^^^^^^
  File "/home/airflow/.local/lib/python3.12/site-packages/airflow/models/baseoperator.py", line 424, in wrapper
    return func(self, *args, **kwargs)
           ^^^^^^^^^^^^^^^^^^^^^^^^^^^
  File "/home/airflow/.local/lib/python3.12/site-packages/airflow/operators/python.py", line 238, in execute
    return_value = self.execute_callable()
                   ^^^^^^^^^^^^^^^^^^^^^^^
  File "/home/airflow/.local/lib/python3.12/site-packages/airflow/operators/python.py", line 256, in execute_callable
    return runner.run(*self.op_args, **self.op_kwargs)
           ^^^^^^^^^^^^^^^^^^^^^^^^^^^^^^^^^^^^^^^^^^^
  File "/home/airflow/.local/lib/python3.12/site-packages/airflow/utils/operator_helpers.py", line 252, in run
    return self.func(*args, **kwargs)
           ^^^^^^^^^^^^^^^^^^^^^^^^^^
  File "/opt/airflow/dags/gsheet_dag.py", line 52, in upload_to_gsheets
    spreadsheet = client.open(spreadsheet_name)
                  ^^^^^^^^^^^^^^^^^^^^^^^^^^^^^
  File "/home/airflow/.local/lib/python3.12/site-packages/gspread/client.py", line 145, in open
    spreadsheet_files, response = self._list_spreadsheet_files(title, folder_id)
                                  ^^^^^^^^^^^^^^^^^^^^^^^^^^^^^^^^^^^^^^^^^^^^^^
  File "/home/airflow/.local/lib/python3.12/site-packages/gspread/client.py", line 118, in _list_spreadsheet_files
    response = self.http_client.request("get", url, params=params)
               ^^^^^^^^^^^^^^^^^^^^^^^^^^^^^^^^^^^^^^^^^^^^^^^^^^^
  File "/home/airflow/.local/lib/python3.12/site-packages/gspread/http_client.py", line 128, in request
    raise APIError(response)
gspread.exceptions.APIError: APIError: [403]: Google Drive API has not been used in project 8983724554 before or it is disabled. Enable it by visiting https://console.developers.google.com/apis/api/drive.googleapis.com/overview?project=8983724554 then retry. If you enabled this API recently, wait a few minutes for the action to propagate to our systems and retry.
[2025-03-16T05:31:13.186+0000] {logging_mixin.py:190} INFO - Task instance in failure state
[2025-03-16T05:31:13.186+0000] {logging_mixin.py:190} INFO - Task start:2025-03-16 05:31:12.186418+00:00 end:2025-03-16 05:31:13.186145+00:00 duration:0.999727
[2025-03-16T05:31:13.186+0000] {logging_mixin.py:190} INFO - Task:<Task(PythonOperator): upload_data_to_gsheets> dag:<DAG: upload_to_gsheets> dagrun:<DagRun upload_to_gsheets @ 2025-03-16 05:31:10.648351+00:00: manual__2025-03-16T05:31:10.648351+00:00, state:running, queued_at: 2025-03-16 05:31:10.655815+00:00. externally triggered: True>
[2025-03-16T05:31:13.186+0000] {logging_mixin.py:190} INFO - Failure caused by APIError: [403]: Google Drive API has not been used in project 8983724554 before or it is disabled. Enable it by visiting https://console.developers.google.com/apis/api/drive.googleapis.com/overview?project=8983724554 then retry. If you enabled this API recently, wait a few minutes for the action to propagate to our systems and retry.
[2025-03-16T05:31:13.187+0000] {taskinstance.py:1226} INFO - Marking task as UP_FOR_RETRY. dag_id=upload_to_gsheets, task_id=upload_data_to_gsheets, run_id=manual__2025-03-16T05:31:10.648351+00:00, execution_date=20250316T053110, start_date=20250316T053112, end_date=20250316T053113
[2025-03-16T05:31:13.235+0000] {taskinstance.py:341} INFO - ::group::Post task execution logs
[2025-03-16T05:31:13.236+0000] {standard_task_runner.py:124} ERROR - Failed to execute job 260 for task upload_data_to_gsheets (APIError: [403]: Google Drive API has not been used in project 8983724554 before or it is disabled. Enable it by visiting https://console.developers.google.com/apis/api/drive.googleapis.com/overview?project=8983724554 then retry. If you enabled this API recently, wait a few minutes for the action to propagate to our systems and retry.; 116)
Traceback (most recent call last):
  File "/home/airflow/.local/lib/python3.12/site-packages/airflow/task/task_runner/standard_task_runner.py", line 117, in _start_by_fork
    ret = args.func(args, dag=self.dag)
          ^^^^^^^^^^^^^^^^^^^^^^^^^^^^^
  File "/home/airflow/.local/lib/python3.12/site-packages/airflow/cli/cli_config.py", line 49, in command
    return func(*args, **kwargs)
           ^^^^^^^^^^^^^^^^^^^^^
  File "/home/airflow/.local/lib/python3.12/site-packages/airflow/utils/cli.py", line 116, in wrapper
    return f(*args, **kwargs)
           ^^^^^^^^^^^^^^^^^^
  File "/home/airflow/.local/lib/python3.12/site-packages/airflow/cli/commands/task_command.py", line 483, in task_run
    task_return_code = _run_task_by_selected_method(args, _dag, ti)
                       ^^^^^^^^^^^^^^^^^^^^^^^^^^^^^^^^^^^^^^^^^^^^
  File "/home/airflow/.local/lib/python3.12/site-packages/airflow/cli/commands/task_command.py", line 256, in _run_task_by_selected_method
    return _run_raw_task(args, ti)
           ^^^^^^^^^^^^^^^^^^^^^^^
  File "/home/airflow/.local/lib/python3.12/site-packages/airflow/cli/commands/task_command.py", line 341, in _run_raw_task
    return ti._run_raw_task(
           ^^^^^^^^^^^^^^^^^
  File "/home/airflow/.local/lib/python3.12/site-packages/airflow/utils/session.py", line 97, in wrapper
    return func(*args, session=session, **kwargs)
           ^^^^^^^^^^^^^^^^^^^^^^^^^^^^^^^^^^^^^^
  File "/home/airflow/.local/lib/python3.12/site-packages/airflow/models/taskinstance.py", line 3006, in _run_raw_task
    return _run_raw_task(
           ^^^^^^^^^^^^^^
  File "/home/airflow/.local/lib/python3.12/site-packages/airflow/models/taskinstance.py", line 274, in _run_raw_task
    TaskInstance._execute_task_with_callbacks(
  File "/home/airflow/.local/lib/python3.12/site-packages/airflow/models/taskinstance.py", line 3161, in _execute_task_with_callbacks
    result = self._execute_task(context, task_orig)
             ^^^^^^^^^^^^^^^^^^^^^^^^^^^^^^^^^^^^^^
  File "/home/airflow/.local/lib/python3.12/site-packages/airflow/models/taskinstance.py", line 3185, in _execute_task
    return _execute_task(self, context, task_orig)
           ^^^^^^^^^^^^^^^^^^^^^^^^^^^^^^^^^^^^^^^
  File "/home/airflow/.local/lib/python3.12/site-packages/airflow/models/taskinstance.py", line 768, in _execute_task
    result = _execute_callable(context=context, **execute_callable_kwargs)
             ^^^^^^^^^^^^^^^^^^^^^^^^^^^^^^^^^^^^^^^^^^^^^^^^^^^^^^^^^^^^^
  File "/home/airflow/.local/lib/python3.12/site-packages/airflow/models/taskinstance.py", line 734, in _execute_callable
    return ExecutionCallableRunner(
           ^^^^^^^^^^^^^^^^^^^^^^^^
  File "/home/airflow/.local/lib/python3.12/site-packages/airflow/utils/operator_helpers.py", line 252, in run
    return self.func(*args, **kwargs)
           ^^^^^^^^^^^^^^^^^^^^^^^^^^
  File "/home/airflow/.local/lib/python3.12/site-packages/airflow/models/baseoperator.py", line 424, in wrapper
    return func(self, *args, **kwargs)
           ^^^^^^^^^^^^^^^^^^^^^^^^^^^
  File "/home/airflow/.local/lib/python3.12/site-packages/airflow/operators/python.py", line 238, in execute
    return_value = self.execute_callable()
                   ^^^^^^^^^^^^^^^^^^^^^^^
  File "/home/airflow/.local/lib/python3.12/site-packages/airflow/operators/python.py", line 256, in execute_callable
    return runner.run(*self.op_args, **self.op_kwargs)
           ^^^^^^^^^^^^^^^^^^^^^^^^^^^^^^^^^^^^^^^^^^^
  File "/home/airflow/.local/lib/python3.12/site-packages/airflow/utils/operator_helpers.py", line 252, in run
    return self.func(*args, **kwargs)
           ^^^^^^^^^^^^^^^^^^^^^^^^^^
  File "/opt/airflow/dags/gsheet_dag.py", line 52, in upload_to_gsheets
    spreadsheet = client.open(spreadsheet_name)
                  ^^^^^^^^^^^^^^^^^^^^^^^^^^^^^
  File "/home/airflow/.local/lib/python3.12/site-packages/gspread/client.py", line 145, in open
    spreadsheet_files, response = self._list_spreadsheet_files(title, folder_id)
                                  ^^^^^^^^^^^^^^^^^^^^^^^^^^^^^^^^^^^^^^^^^^^^^^
  File "/home/airflow/.local/lib/python3.12/site-packages/gspread/client.py", line 118, in _list_spreadsheet_files
    response = self.http_client.request("get", url, params=params)
               ^^^^^^^^^^^^^^^^^^^^^^^^^^^^^^^^^^^^^^^^^^^^^^^^^^^
  File "/home/airflow/.local/lib/python3.12/site-packages/gspread/http_client.py", line 128, in request
    raise APIError(response)
gspread.exceptions.APIError: APIError: [403]: Google Drive API has not been used in project 8983724554 before or it is disabled. Enable it by visiting https://console.developers.google.com/apis/api/drive.googleapis.com/overview?project=8983724554 then retry. If you enabled this API recently, wait a few minutes for the action to propagate to our systems and retry.
[2025-03-16T05:31:13.265+0000] {local_task_job_runner.py:266} INFO - Task exited with return code 1
[2025-03-16T05:31:13.272+0000] {taskinstance.py:3901} INFO - 0 downstream tasks scheduled from follow-on schedule check
[2025-03-16T05:31:13.273+0000] {local_task_job_runner.py:245} INFO - ::endgroup::
