[2025-03-24T03:43:01.089+0000] {local_task_job_runner.py:123} INFO - ::group::Pre task execution logs
[2025-03-24T03:43:01.094+0000] {taskinstance.py:2614} INFO - Dependencies all met for dep_context=non-requeueable deps ti=<TaskInstance: upload_to_gsheets.upload_data_to_gsheets manual__2025-03-24T03:42:58.686015+00:00 [queued]>
[2025-03-24T03:43:01.096+0000] {taskinstance.py:2614} INFO - Dependencies all met for dep_context=requeueable deps ti=<TaskInstance: upload_to_gsheets.upload_data_to_gsheets manual__2025-03-24T03:42:58.686015+00:00 [queued]>
[2025-03-24T03:43:01.096+0000] {taskinstance.py:2867} INFO - Starting attempt 1 of 2
[2025-03-24T03:43:01.100+0000] {taskinstance.py:2890} INFO - Executing <Task(PythonOperator): upload_data_to_gsheets> on 2025-03-24 03:42:58.686015+00:00
[2025-03-24T03:43:01.102+0000] {warnings.py:112} WARNING - /home/***/.local/lib/python3.12/site-packages/***/task/task_runner/standard_task_runner.py:70: DeprecationWarning: This process (pid=482) is multi-threaded, use of fork() may lead to deadlocks in the child.
  pid = os.fork()

[2025-03-24T03:43:01.103+0000] {standard_task_runner.py:72} INFO - Started process 494 to run task
[2025-03-24T03:43:01.103+0000] {standard_task_runner.py:104} INFO - Running: ['***', 'tasks', 'run', 'upload_to_gsheets', 'upload_data_to_gsheets', 'manual__2025-03-24T03:42:58.686015+00:00', '--job-id', '303', '--raw', '--subdir', 'DAGS_FOLDER/gsheet_dag.py', '--cfg-path', '/tmp/tmpdbnj4rnz']
[2025-03-24T03:43:01.103+0000] {standard_task_runner.py:105} INFO - Job 303: Subtask upload_data_to_gsheets
[2025-03-24T03:43:01.117+0000] {task_command.py:467} INFO - Running <TaskInstance: upload_to_gsheets.upload_data_to_gsheets manual__2025-03-24T03:42:58.686015+00:00 [running]> on host bba58eafeea6
[2025-03-24T03:43:01.142+0000] {taskinstance.py:3134} INFO - Exporting env vars: AIRFLOW_CTX_DAG_OWNER='***' AIRFLOW_CTX_DAG_ID='upload_to_gsheets' AIRFLOW_CTX_TASK_ID='upload_data_to_gsheets' AIRFLOW_CTX_EXECUTION_DATE='2025-03-24T03:42:58.686015+00:00' AIRFLOW_CTX_TRY_NUMBER='1' AIRFLOW_CTX_DAG_RUN_ID='manual__2025-03-24T03:42:58.686015+00:00'
[2025-03-24T03:43:01.142+0000] {logging_mixin.py:190} INFO - Task instance is in running state
[2025-03-24T03:43:01.143+0000] {logging_mixin.py:190} INFO -  Previous state of the Task instance: queued
[2025-03-24T03:43:01.143+0000] {logging_mixin.py:190} INFO - Current task name:upload_data_to_gsheets state:running start_date:2025-03-24 03:43:01.094800+00:00
[2025-03-24T03:43:01.143+0000] {logging_mixin.py:190} INFO - Dag name:upload_to_gsheets and current dag run status:running
[2025-03-24T03:43:01.143+0000] {taskinstance.py:732} INFO - ::endgroup::
[2025-03-24T03:43:26.649+0000] {taskinstance.py:3313} ERROR - Task failed with exception
Traceback (most recent call last):
  File "/home/airflow/.local/lib/python3.12/site-packages/sqlalchemy/engine/base.py", line 1910, in _execute_context
    self.dialect.do_execute(
  File "/home/airflow/.local/lib/python3.12/site-packages/sqlalchemy/engine/default.py", line 736, in do_execute
    cursor.execute(statement, parameters)
psycopg2.errors.UndefinedTable: relation "naver_news" does not exist
LINE 1: SELECT * FROM naver_news
                      ^


The above exception was the direct cause of the following exception:

Traceback (most recent call last):
  File "/home/airflow/.local/lib/python3.12/site-packages/airflow/models/taskinstance.py", line 768, in _execute_task
    result = _execute_callable(context=context, **execute_callable_kwargs)
             ^^^^^^^^^^^^^^^^^^^^^^^^^^^^^^^^^^^^^^^^^^^^^^^^^^^^^^^^^^^^^
  File "/home/airflow/.local/lib/python3.12/site-packages/airflow/models/taskinstance.py", line 734, in _execute_callable
    return ExecutionCallableRunner(
           ^^^^^^^^^^^^^^^^^^^^^^^^
  File "/home/airflow/.local/lib/python3.12/site-packages/airflow/utils/operator_helpers.py", line 252, in run
    return self.func(*args, **kwargs)
           ^^^^^^^^^^^^^^^^^^^^^^^^^^
  File "/home/airflow/.local/lib/python3.12/site-packages/airflow/models/baseoperator.py", line 424, in wrapper
    return func(self, *args, **kwargs)
           ^^^^^^^^^^^^^^^^^^^^^^^^^^^
  File "/home/airflow/.local/lib/python3.12/site-packages/airflow/operators/python.py", line 238, in execute
    return_value = self.execute_callable()
                   ^^^^^^^^^^^^^^^^^^^^^^^
  File "/home/airflow/.local/lib/python3.12/site-packages/airflow/operators/python.py", line 256, in execute_callable
    return runner.run(*self.op_args, **self.op_kwargs)
           ^^^^^^^^^^^^^^^^^^^^^^^^^^^^^^^^^^^^^^^^^^^
  File "/home/airflow/.local/lib/python3.12/site-packages/airflow/utils/operator_helpers.py", line 252, in run
    return self.func(*args, **kwargs)
           ^^^^^^^^^^^^^^^^^^^^^^^^^^
  File "/opt/airflow/dags/gsheet_dag.py", line 64, in upload_to_gsheets
    df = pd.read_sql(query, engine)
         ^^^^^^^^^^^^^^^^^^^^^^^^^^
  File "/home/airflow/.local/lib/python3.12/site-packages/pandas/io/sql.py", line 682, in read_sql
    return pandas_sql.read_query(
           ^^^^^^^^^^^^^^^^^^^^^^
  File "/home/airflow/.local/lib/python3.12/site-packages/pandas/io/sql.py", line 1776, in read_query
    result = self.execute(sql, params)
             ^^^^^^^^^^^^^^^^^^^^^^^^^
  File "/home/airflow/.local/lib/python3.12/site-packages/pandas/io/sql.py", line 1599, in execute
    return self.con.exec_driver_sql(sql, *args)
           ^^^^^^^^^^^^^^^^^^^^^^^^^^^^^^^^^^^^
  File "/home/airflow/.local/lib/python3.12/site-packages/sqlalchemy/engine/base.py", line 1770, in exec_driver_sql
    return self._exec_driver_sql(
           ^^^^^^^^^^^^^^^^^^^^^^
  File "/home/airflow/.local/lib/python3.12/site-packages/sqlalchemy/engine/base.py", line 1674, in _exec_driver_sql
    ret = self._execute_context(
          ^^^^^^^^^^^^^^^^^^^^^^
  File "/home/airflow/.local/lib/python3.12/site-packages/sqlalchemy/engine/base.py", line 1953, in _execute_context
    self._handle_dbapi_exception(
  File "/home/airflow/.local/lib/python3.12/site-packages/sqlalchemy/engine/base.py", line 2134, in _handle_dbapi_exception
    util.raise_(
  File "/home/airflow/.local/lib/python3.12/site-packages/sqlalchemy/util/compat.py", line 211, in raise_
    raise exception
  File "/home/airflow/.local/lib/python3.12/site-packages/sqlalchemy/engine/base.py", line 1910, in _execute_context
    self.dialect.do_execute(
  File "/home/airflow/.local/lib/python3.12/site-packages/sqlalchemy/engine/default.py", line 736, in do_execute
    cursor.execute(statement, parameters)
sqlalchemy.exc.ProgrammingError: (psycopg2.errors.UndefinedTable) relation "naver_news" does not exist
LINE 1: SELECT * FROM naver_news
                      ^

[SQL: SELECT * FROM naver_news]
(Background on this error at: https://sqlalche.me/e/14/f405)
[2025-03-24T03:43:26.666+0000] {logging_mixin.py:190} INFO - Task instance in failure state
[2025-03-24T03:43:26.667+0000] {logging_mixin.py:190} INFO - Task start:2025-03-24 03:43:01.094800+00:00 end:2025-03-24 03:43:26.666382+00:00 duration:25.571582
[2025-03-24T03:43:26.667+0000] {logging_mixin.py:190} INFO - Task:<Task(PythonOperator): upload_data_to_gsheets> dag:<DAG: upload_to_gsheets> dagrun:<DagRun upload_to_gsheets @ 2025-03-24 03:42:58.686015+00:00: manual__2025-03-24T03:42:58.686015+00:00, state:running, queued_at: 2025-03-24 03:42:58.693481+00:00. externally triggered: True>
[2025-03-24T03:43:26.667+0000] {logging_mixin.py:190} INFO - Failure caused by (psycopg2.errors.UndefinedTable) relation "naver_news" does not exist
LINE 1: SELECT * FROM naver_news
                      ^

[SQL: SELECT * FROM naver_news]
(Background on this error at: https://sqlalche.me/e/14/f405)
[2025-03-24T03:43:26.668+0000] {taskinstance.py:1226} INFO - Marking task as UP_FOR_RETRY. dag_id=upload_to_gsheets, task_id=upload_data_to_gsheets, run_id=manual__2025-03-24T03:42:58.686015+00:00, execution_date=20250324T034258, start_date=20250324T034301, end_date=20250324T034326
[2025-03-24T03:43:26.685+0000] {taskinstance.py:341} INFO - ::group::Post task execution logs
[2025-03-24T03:43:26.686+0000] {standard_task_runner.py:124} ERROR - Failed to execute job 303 for task upload_data_to_gsheets ((psycopg2.errors.UndefinedTable) relation "naver_news" does not exist
LINE 1: SELECT * FROM naver_news
                      ^

[SQL: SELECT * FROM naver_news]
(Background on this error at: https://sqlalche.me/e/14/f405); 494)
Traceback (most recent call last):
  File "/home/airflow/.local/lib/python3.12/site-packages/sqlalchemy/engine/base.py", line 1910, in _execute_context
    self.dialect.do_execute(
  File "/home/airflow/.local/lib/python3.12/site-packages/sqlalchemy/engine/default.py", line 736, in do_execute
    cursor.execute(statement, parameters)
psycopg2.errors.UndefinedTable: relation "naver_news" does not exist
LINE 1: SELECT * FROM naver_news
                      ^


The above exception was the direct cause of the following exception:

Traceback (most recent call last):
  File "/home/airflow/.local/lib/python3.12/site-packages/airflow/task/task_runner/standard_task_runner.py", line 117, in _start_by_fork
    ret = args.func(args, dag=self.dag)
          ^^^^^^^^^^^^^^^^^^^^^^^^^^^^^
  File "/home/airflow/.local/lib/python3.12/site-packages/airflow/cli/cli_config.py", line 49, in command
    return func(*args, **kwargs)
           ^^^^^^^^^^^^^^^^^^^^^
  File "/home/airflow/.local/lib/python3.12/site-packages/airflow/utils/cli.py", line 116, in wrapper
    return f(*args, **kwargs)
           ^^^^^^^^^^^^^^^^^^
  File "/home/airflow/.local/lib/python3.12/site-packages/airflow/cli/commands/task_command.py", line 483, in task_run
    task_return_code = _run_task_by_selected_method(args, _dag, ti)
                       ^^^^^^^^^^^^^^^^^^^^^^^^^^^^^^^^^^^^^^^^^^^^
  File "/home/airflow/.local/lib/python3.12/site-packages/airflow/cli/commands/task_command.py", line 256, in _run_task_by_selected_method
    return _run_raw_task(args, ti)
           ^^^^^^^^^^^^^^^^^^^^^^^
  File "/home/airflow/.local/lib/python3.12/site-packages/airflow/cli/commands/task_command.py", line 341, in _run_raw_task
    return ti._run_raw_task(
           ^^^^^^^^^^^^^^^^^
  File "/home/airflow/.local/lib/python3.12/site-packages/airflow/utils/session.py", line 97, in wrapper
    return func(*args, session=session, **kwargs)
           ^^^^^^^^^^^^^^^^^^^^^^^^^^^^^^^^^^^^^^
  File "/home/airflow/.local/lib/python3.12/site-packages/airflow/models/taskinstance.py", line 3006, in _run_raw_task
    return _run_raw_task(
           ^^^^^^^^^^^^^^
  File "/home/airflow/.local/lib/python3.12/site-packages/airflow/models/taskinstance.py", line 274, in _run_raw_task
    TaskInstance._execute_task_with_callbacks(
  File "/home/airflow/.local/lib/python3.12/site-packages/airflow/models/taskinstance.py", line 3161, in _execute_task_with_callbacks
    result = self._execute_task(context, task_orig)
             ^^^^^^^^^^^^^^^^^^^^^^^^^^^^^^^^^^^^^^
  File "/home/airflow/.local/lib/python3.12/site-packages/airflow/models/taskinstance.py", line 3185, in _execute_task
    return _execute_task(self, context, task_orig)
           ^^^^^^^^^^^^^^^^^^^^^^^^^^^^^^^^^^^^^^^
  File "/home/airflow/.local/lib/python3.12/site-packages/airflow/models/taskinstance.py", line 768, in _execute_task
    result = _execute_callable(context=context, **execute_callable_kwargs)
             ^^^^^^^^^^^^^^^^^^^^^^^^^^^^^^^^^^^^^^^^^^^^^^^^^^^^^^^^^^^^^
  File "/home/airflow/.local/lib/python3.12/site-packages/airflow/models/taskinstance.py", line 734, in _execute_callable
    return ExecutionCallableRunner(
           ^^^^^^^^^^^^^^^^^^^^^^^^
  File "/home/airflow/.local/lib/python3.12/site-packages/airflow/utils/operator_helpers.py", line 252, in run
    return self.func(*args, **kwargs)
           ^^^^^^^^^^^^^^^^^^^^^^^^^^
  File "/home/airflow/.local/lib/python3.12/site-packages/airflow/models/baseoperator.py", line 424, in wrapper
    return func(self, *args, **kwargs)
           ^^^^^^^^^^^^^^^^^^^^^^^^^^^
  File "/home/airflow/.local/lib/python3.12/site-packages/airflow/operators/python.py", line 238, in execute
    return_value = self.execute_callable()
                   ^^^^^^^^^^^^^^^^^^^^^^^
  File "/home/airflow/.local/lib/python3.12/site-packages/airflow/operators/python.py", line 256, in execute_callable
    return runner.run(*self.op_args, **self.op_kwargs)
           ^^^^^^^^^^^^^^^^^^^^^^^^^^^^^^^^^^^^^^^^^^^
  File "/home/airflow/.local/lib/python3.12/site-packages/airflow/utils/operator_helpers.py", line 252, in run
    return self.func(*args, **kwargs)
           ^^^^^^^^^^^^^^^^^^^^^^^^^^
  File "/opt/airflow/dags/gsheet_dag.py", line 64, in upload_to_gsheets
    df = pd.read_sql(query, engine)
         ^^^^^^^^^^^^^^^^^^^^^^^^^^
  File "/home/airflow/.local/lib/python3.12/site-packages/pandas/io/sql.py", line 682, in read_sql
    return pandas_sql.read_query(
           ^^^^^^^^^^^^^^^^^^^^^^
  File "/home/airflow/.local/lib/python3.12/site-packages/pandas/io/sql.py", line 1776, in read_query
    result = self.execute(sql, params)
             ^^^^^^^^^^^^^^^^^^^^^^^^^
  File "/home/airflow/.local/lib/python3.12/site-packages/pandas/io/sql.py", line 1599, in execute
    return self.con.exec_driver_sql(sql, *args)
           ^^^^^^^^^^^^^^^^^^^^^^^^^^^^^^^^^^^^
  File "/home/airflow/.local/lib/python3.12/site-packages/sqlalchemy/engine/base.py", line 1770, in exec_driver_sql
    return self._exec_driver_sql(
           ^^^^^^^^^^^^^^^^^^^^^^
  File "/home/airflow/.local/lib/python3.12/site-packages/sqlalchemy/engine/base.py", line 1674, in _exec_driver_sql
    ret = self._execute_context(
          ^^^^^^^^^^^^^^^^^^^^^^
  File "/home/airflow/.local/lib/python3.12/site-packages/sqlalchemy/engine/base.py", line 1953, in _execute_context
    self._handle_dbapi_exception(
  File "/home/airflow/.local/lib/python3.12/site-packages/sqlalchemy/engine/base.py", line 2134, in _handle_dbapi_exception
    util.raise_(
  File "/home/airflow/.local/lib/python3.12/site-packages/sqlalchemy/util/compat.py", line 211, in raise_
    raise exception
  File "/home/airflow/.local/lib/python3.12/site-packages/sqlalchemy/engine/base.py", line 1910, in _execute_context
    self.dialect.do_execute(
  File "/home/airflow/.local/lib/python3.12/site-packages/sqlalchemy/engine/default.py", line 736, in do_execute
    cursor.execute(statement, parameters)
sqlalchemy.exc.ProgrammingError: (psycopg2.errors.UndefinedTable) relation "naver_news" does not exist
LINE 1: SELECT * FROM naver_news
                      ^

[SQL: SELECT * FROM naver_news]
(Background on this error at: https://sqlalche.me/e/14/f405)
[2025-03-24T03:43:26.728+0000] {local_task_job_runner.py:266} INFO - Task exited with return code 1
[2025-03-24T03:43:26.738+0000] {taskinstance.py:3901} INFO - 0 downstream tasks scheduled from follow-on schedule check
[2025-03-24T03:43:26.739+0000] {local_task_job_runner.py:245} INFO - ::endgroup::
