[2025-03-16T02:43:59.278+0000] {local_task_job_runner.py:123} INFO - ::group::Pre task execution logs
[2025-03-16T02:43:59.287+0000] {taskinstance.py:2614} INFO - Dependencies all met for dep_context=non-requeueable deps ti=<TaskInstance: trend_dag.extract manual__2025-03-16T02:43:53.610689+00:00 [queued]>
[2025-03-16T02:43:59.291+0000] {taskinstance.py:2614} INFO - Dependencies all met for dep_context=requeueable deps ti=<TaskInstance: trend_dag.extract manual__2025-03-16T02:43:53.610689+00:00 [queued]>
[2025-03-16T02:43:59.291+0000] {taskinstance.py:2867} INFO - Starting attempt 1 of 2
[2025-03-16T02:43:59.299+0000] {taskinstance.py:2890} INFO - Executing <Task(PythonOperator): extract> on 2025-03-16 02:43:53.610689+00:00
[2025-03-16T02:43:59.303+0000] {warnings.py:112} WARNING - /home/***/.local/lib/python3.12/site-packages/***/task/task_runner/standard_task_runner.py:70: DeprecationWarning: This process (pid=118) is multi-threaded, use of fork() may lead to deadlocks in the child.
  pid = os.fork()

[2025-03-16T02:43:59.304+0000] {standard_task_runner.py:72} INFO - Started process 119 to run task
[2025-03-16T02:43:59.304+0000] {standard_task_runner.py:104} INFO - Running: ['***', 'tasks', 'run', 'trend_dag', 'extract', 'manual__2025-03-16T02:43:53.610689+00:00', '--job-id', '249', '--raw', '--subdir', 'DAGS_FOLDER/trend_dag.py', '--cfg-path', '/tmp/tmpitkdp7s9']
[2025-03-16T02:43:59.305+0000] {standard_task_runner.py:105} INFO - Job 249: Subtask extract
[2025-03-16T02:43:59.332+0000] {task_command.py:467} INFO - Running <TaskInstance: trend_dag.extract manual__2025-03-16T02:43:53.610689+00:00 [running]> on host 4f8a3a82033b
[2025-03-16T02:43:59.370+0000] {taskinstance.py:3134} INFO - Exporting env vars: AIRFLOW_CTX_DAG_OWNER='***' AIRFLOW_CTX_DAG_ID='trend_dag' AIRFLOW_CTX_TASK_ID='extract' AIRFLOW_CTX_EXECUTION_DATE='2025-03-16T02:43:53.610689+00:00' AIRFLOW_CTX_TRY_NUMBER='1' AIRFLOW_CTX_DAG_RUN_ID='manual__2025-03-16T02:43:53.610689+00:00'
[2025-03-16T02:43:59.371+0000] {logging_mixin.py:190} INFO - Task instance is in running state
[2025-03-16T02:43:59.373+0000] {logging_mixin.py:190} INFO -  Previous state of the Task instance: queued
[2025-03-16T02:43:59.374+0000] {logging_mixin.py:190} INFO - Current task name:extract state:running start_date:2025-03-16 02:43:59.287851+00:00
[2025-03-16T02:43:59.374+0000] {logging_mixin.py:190} INFO - Dag name:trend_dag and current dag run status:running
[2025-03-16T02:43:59.375+0000] {taskinstance.py:732} INFO - ::endgroup::
[2025-03-16T02:45:34.259+0000] {taskinstance.py:3313} ERROR - Task failed with exception
Traceback (most recent call last):
  File "/home/airflow/.local/lib/python3.12/site-packages/airflow/models/taskinstance.py", line 768, in _execute_task
    result = _execute_callable(context=context, **execute_callable_kwargs)
             ^^^^^^^^^^^^^^^^^^^^^^^^^^^^^^^^^^^^^^^^^^^^^^^^^^^^^^^^^^^^^
  File "/home/airflow/.local/lib/python3.12/site-packages/airflow/models/taskinstance.py", line 734, in _execute_callable
    return ExecutionCallableRunner(
           ^^^^^^^^^^^^^^^^^^^^^^^^
  File "/home/airflow/.local/lib/python3.12/site-packages/airflow/utils/operator_helpers.py", line 252, in run
    return self.func(*args, **kwargs)
           ^^^^^^^^^^^^^^^^^^^^^^^^^^
  File "/home/airflow/.local/lib/python3.12/site-packages/airflow/models/baseoperator.py", line 424, in wrapper
    return func(self, *args, **kwargs)
           ^^^^^^^^^^^^^^^^^^^^^^^^^^^
  File "/home/airflow/.local/lib/python3.12/site-packages/airflow/operators/python.py", line 238, in execute
    return_value = self.execute_callable()
                   ^^^^^^^^^^^^^^^^^^^^^^^
  File "/home/airflow/.local/lib/python3.12/site-packages/airflow/operators/python.py", line 256, in execute_callable
    return runner.run(*self.op_args, **self.op_kwargs)
           ^^^^^^^^^^^^^^^^^^^^^^^^^^^^^^^^^^^^^^^^^^^
  File "/home/airflow/.local/lib/python3.12/site-packages/airflow/utils/operator_helpers.py", line 252, in run
    return self.func(*args, **kwargs)
           ^^^^^^^^^^^^^^^^^^^^^^^^^^
  File "/opt/airflow/plugins/scripts/extract/trend_extract.py", line 48, in extract_trend_data
    df = pytrends.interest_over_time()
         ^^^^^^^^^^^^^^^^^^^^^^^^^^^^^
  File "/home/airflow/.local/lib/python3.12/site-packages/pytrends/request.py", line 232, in interest_over_time
    req_json = self._get_data(
               ^^^^^^^^^^^^^^^
  File "/home/airflow/.local/lib/python3.12/site-packages/pytrends/request.py", line 159, in _get_data
    raise exceptions.TooManyRequestsError.from_response(response)
pytrends.exceptions.TooManyRequestsError: The request failed: Google returned a response with code 429
[2025-03-16T02:45:34.301+0000] {logging_mixin.py:190} INFO - Task instance in failure state
[2025-03-16T02:45:34.303+0000] {logging_mixin.py:190} INFO - Task start:2025-03-16 02:43:59.287851+00:00 end:2025-03-16 02:45:34.296017+00:00 duration:95.008166
[2025-03-16T02:45:34.307+0000] {logging_mixin.py:190} INFO - Task:<Task(PythonOperator): extract> dag:<DAG: trend_dag> dagrun:<DagRun trend_dag @ 2025-03-16 02:43:53.610689+00:00: manual__2025-03-16T02:43:53.610689+00:00, state:running, queued_at: 2025-03-16 02:43:53.631052+00:00. externally triggered: True>
[2025-03-16T02:45:34.308+0000] {logging_mixin.py:190} INFO - Failure caused by The request failed: Google returned a response with code 429
[2025-03-16T02:45:34.310+0000] {taskinstance.py:1226} INFO - Marking task as UP_FOR_RETRY. dag_id=trend_dag, task_id=extract, run_id=manual__2025-03-16T02:43:53.610689+00:00, execution_date=20250316T024353, start_date=20250316T024359, end_date=20250316T024534
[2025-03-16T02:45:34.454+0000] {taskinstance.py:341} INFO - ::group::Post task execution logs
[2025-03-16T02:45:34.464+0000] {standard_task_runner.py:124} ERROR - Failed to execute job 249 for task extract (The request failed: Google returned a response with code 429; 119)
Traceback (most recent call last):
  File "/home/airflow/.local/lib/python3.12/site-packages/airflow/task/task_runner/standard_task_runner.py", line 117, in _start_by_fork
    ret = args.func(args, dag=self.dag)
          ^^^^^^^^^^^^^^^^^^^^^^^^^^^^^
  File "/home/airflow/.local/lib/python3.12/site-packages/airflow/cli/cli_config.py", line 49, in command
    return func(*args, **kwargs)
           ^^^^^^^^^^^^^^^^^^^^^
  File "/home/airflow/.local/lib/python3.12/site-packages/airflow/utils/cli.py", line 116, in wrapper
    return f(*args, **kwargs)
           ^^^^^^^^^^^^^^^^^^
  File "/home/airflow/.local/lib/python3.12/site-packages/airflow/cli/commands/task_command.py", line 483, in task_run
    task_return_code = _run_task_by_selected_method(args, _dag, ti)
                       ^^^^^^^^^^^^^^^^^^^^^^^^^^^^^^^^^^^^^^^^^^^^
  File "/home/airflow/.local/lib/python3.12/site-packages/airflow/cli/commands/task_command.py", line 256, in _run_task_by_selected_method
    return _run_raw_task(args, ti)
           ^^^^^^^^^^^^^^^^^^^^^^^
  File "/home/airflow/.local/lib/python3.12/site-packages/airflow/cli/commands/task_command.py", line 341, in _run_raw_task
    return ti._run_raw_task(
           ^^^^^^^^^^^^^^^^^
  File "/home/airflow/.local/lib/python3.12/site-packages/airflow/utils/session.py", line 97, in wrapper
    return func(*args, session=session, **kwargs)
           ^^^^^^^^^^^^^^^^^^^^^^^^^^^^^^^^^^^^^^
  File "/home/airflow/.local/lib/python3.12/site-packages/airflow/models/taskinstance.py", line 3006, in _run_raw_task
    return _run_raw_task(
           ^^^^^^^^^^^^^^
  File "/home/airflow/.local/lib/python3.12/site-packages/airflow/models/taskinstance.py", line 274, in _run_raw_task
    TaskInstance._execute_task_with_callbacks(
  File "/home/airflow/.local/lib/python3.12/site-packages/airflow/models/taskinstance.py", line 3161, in _execute_task_with_callbacks
    result = self._execute_task(context, task_orig)
             ^^^^^^^^^^^^^^^^^^^^^^^^^^^^^^^^^^^^^^
  File "/home/airflow/.local/lib/python3.12/site-packages/airflow/models/taskinstance.py", line 3185, in _execute_task
    return _execute_task(self, context, task_orig)
           ^^^^^^^^^^^^^^^^^^^^^^^^^^^^^^^^^^^^^^^
  File "/home/airflow/.local/lib/python3.12/site-packages/airflow/models/taskinstance.py", line 768, in _execute_task
    result = _execute_callable(context=context, **execute_callable_kwargs)
             ^^^^^^^^^^^^^^^^^^^^^^^^^^^^^^^^^^^^^^^^^^^^^^^^^^^^^^^^^^^^^
  File "/home/airflow/.local/lib/python3.12/site-packages/airflow/models/taskinstance.py", line 734, in _execute_callable
    return ExecutionCallableRunner(
           ^^^^^^^^^^^^^^^^^^^^^^^^
  File "/home/airflow/.local/lib/python3.12/site-packages/airflow/utils/operator_helpers.py", line 252, in run
    return self.func(*args, **kwargs)
           ^^^^^^^^^^^^^^^^^^^^^^^^^^
  File "/home/airflow/.local/lib/python3.12/site-packages/airflow/models/baseoperator.py", line 424, in wrapper
    return func(self, *args, **kwargs)
           ^^^^^^^^^^^^^^^^^^^^^^^^^^^
  File "/home/airflow/.local/lib/python3.12/site-packages/airflow/operators/python.py", line 238, in execute
    return_value = self.execute_callable()
                   ^^^^^^^^^^^^^^^^^^^^^^^
  File "/home/airflow/.local/lib/python3.12/site-packages/airflow/operators/python.py", line 256, in execute_callable
    return runner.run(*self.op_args, **self.op_kwargs)
           ^^^^^^^^^^^^^^^^^^^^^^^^^^^^^^^^^^^^^^^^^^^
  File "/home/airflow/.local/lib/python3.12/site-packages/airflow/utils/operator_helpers.py", line 252, in run
    return self.func(*args, **kwargs)
           ^^^^^^^^^^^^^^^^^^^^^^^^^^
  File "/opt/airflow/plugins/scripts/extract/trend_extract.py", line 48, in extract_trend_data
    df = pytrends.interest_over_time()
         ^^^^^^^^^^^^^^^^^^^^^^^^^^^^^
  File "/home/airflow/.local/lib/python3.12/site-packages/pytrends/request.py", line 232, in interest_over_time
    req_json = self._get_data(
               ^^^^^^^^^^^^^^^
  File "/home/airflow/.local/lib/python3.12/site-packages/pytrends/request.py", line 159, in _get_data
    raise exceptions.TooManyRequestsError.from_response(response)
pytrends.exceptions.TooManyRequestsError: The request failed: Google returned a response with code 429
[2025-03-16T02:45:34.496+0000] {local_task_job_runner.py:266} INFO - Task exited with return code 1
[2025-03-16T02:45:34.553+0000] {taskinstance.py:3901} INFO - 0 downstream tasks scheduled from follow-on schedule check
[2025-03-16T02:45:34.558+0000] {local_task_job_runner.py:245} INFO - ::endgroup::
