[2025-03-18T03:06:47.668+0000] {local_task_job_runner.py:123} INFO - ::group::Pre task execution logs
[2025-03-18T03:06:47.674+0000] {taskinstance.py:2614} INFO - Dependencies all met for dep_context=non-requeueable deps ti=<TaskInstance: trend_dag.extract manual__2025-03-18T02:59:47.095990+00:00 [queued]>
[2025-03-18T03:06:47.676+0000] {taskinstance.py:2614} INFO - Dependencies all met for dep_context=requeueable deps ti=<TaskInstance: trend_dag.extract manual__2025-03-18T02:59:47.095990+00:00 [queued]>
[2025-03-18T03:06:47.676+0000] {taskinstance.py:2867} INFO - Starting attempt 2 of 2
[2025-03-18T03:06:47.680+0000] {taskinstance.py:2890} INFO - Executing <Task(PythonOperator): extract> on 2025-03-18 02:59:47.095990+00:00
[2025-03-18T03:06:47.682+0000] {warnings.py:112} WARNING - /home/***/.local/lib/python3.12/site-packages/***/task/task_runner/standard_task_runner.py:70: DeprecationWarning: This process (pid=112) is multi-threaded, use of fork() may lead to deadlocks in the child.
  pid = os.fork()

[2025-03-18T03:06:47.683+0000] {standard_task_runner.py:72} INFO - Started process 113 to run task
[2025-03-18T03:06:47.683+0000] {standard_task_runner.py:104} INFO - Running: ['***', 'tasks', 'run', 'trend_dag', 'extract', 'manual__2025-03-18T02:59:47.095990+00:00', '--job-id', '290', '--raw', '--subdir', 'DAGS_FOLDER/trend_dag.py', '--cfg-path', '/tmp/tmpsks5wjqz']
[2025-03-18T03:06:47.684+0000] {standard_task_runner.py:105} INFO - Job 290: Subtask extract
[2025-03-18T03:06:47.702+0000] {task_command.py:467} INFO - Running <TaskInstance: trend_dag.extract manual__2025-03-18T02:59:47.095990+00:00 [running]> on host d65dcdbed797
[2025-03-18T03:06:47.736+0000] {taskinstance.py:3134} INFO - Exporting env vars: AIRFLOW_CTX_DAG_OWNER='***' AIRFLOW_CTX_DAG_ID='trend_dag' AIRFLOW_CTX_TASK_ID='extract' AIRFLOW_CTX_EXECUTION_DATE='2025-03-18T02:59:47.095990+00:00' AIRFLOW_CTX_TRY_NUMBER='2' AIRFLOW_CTX_DAG_RUN_ID='manual__2025-03-18T02:59:47.095990+00:00'
[2025-03-18T03:06:47.736+0000] {logging_mixin.py:190} INFO - Task instance is in running state
[2025-03-18T03:06:47.737+0000] {logging_mixin.py:190} INFO -  Previous state of the Task instance: queued
[2025-03-18T03:06:47.737+0000] {logging_mixin.py:190} INFO - Current task name:extract state:running start_date:2025-03-18 03:06:47.674331+00:00
[2025-03-18T03:06:47.737+0000] {logging_mixin.py:190} INFO - Dag name:trend_dag and current dag run status:running
[2025-03-18T03:06:47.737+0000] {taskinstance.py:732} INFO - ::endgroup::
[2025-03-18T03:09:24.823+0000] {connectionpool.py:823} WARNING - Retrying (Retry(total=0, connect=5, read=4, redirect=None, status=None)) after connection broken by 'ReadTimeoutError("HTTPSConnectionPool(host='trends.google.com', port=443): Read timed out. (read timeout=5)")': /trends/api/widgetdata/multiline?req=%7B%22time%22%3A+%222024-12-01+2025-03-17%22%2C+%22resolution%22%3A+%22DAY%22%2C+%22locale%22%3A+%22ko%22%2C+%22comparisonItem%22%3A+%5B%7B%22geo%22%3A+%7B%22country%22%3A+%22KR%22%7D%2C+%22complexKeywordsRestriction%22%3A+%7B%22keyword%22%3A+%5B%7B%22type%22%3A+%22BROAD%22%2C+%22value%22%3A+%22%5Cuae40%5Cuacbd%5Cuc218%22%7D%5D%7D%7D%5D%2C+%22requestOptions%22%3A+%7B%22property%22%3A+%22%22%2C+%22backend%22%3A+%22IZG%22%2C+%22category%22%3A+0%7D%2C+%22userConfig%22%3A+%7B%22userType%22%3A+%22USER_TYPE_SCRAPER%22%7D%7D&token=APP6_UEAAAAAZ9o0yA9B1iLv25glt0jcIcZ7QloGojcB&tz=540
[2025-03-18T03:09:25.699+0000] {taskinstance.py:3313} ERROR - Task failed with exception
Traceback (most recent call last):
  File "/home/airflow/.local/lib/python3.12/site-packages/requests/adapters.py", line 667, in send
    resp = conn.urlopen(
           ^^^^^^^^^^^^^
  File "/home/airflow/.local/lib/python3.12/site-packages/urllib3/connectionpool.py", line 889, in urlopen
    return self.urlopen(
           ^^^^^^^^^^^^^
  File "/home/airflow/.local/lib/python3.12/site-packages/urllib3/connectionpool.py", line 889, in urlopen
    return self.urlopen(
           ^^^^^^^^^^^^^
  File "/home/airflow/.local/lib/python3.12/site-packages/urllib3/connectionpool.py", line 889, in urlopen
    return self.urlopen(
           ^^^^^^^^^^^^^
  [Previous line repeated 1 more time]
  File "/home/airflow/.local/lib/python3.12/site-packages/urllib3/connectionpool.py", line 826, in urlopen
    return self.urlopen(
           ^^^^^^^^^^^^^
  File "/home/airflow/.local/lib/python3.12/site-packages/urllib3/connectionpool.py", line 879, in urlopen
    retries = retries.increment(method, url, response=response, _pool=self)
              ^^^^^^^^^^^^^^^^^^^^^^^^^^^^^^^^^^^^^^^^^^^^^^^^^^^^^^^^^^^^^
  File "/home/airflow/.local/lib/python3.12/site-packages/urllib3/util/retry.py", line 592, in increment
    raise MaxRetryError(_pool, url, error or ResponseError(cause))
urllib3.exceptions.MaxRetryError: HTTPSConnectionPool(host='trends.google.com', port=443): Max retries exceeded with url: /trends/api/widgetdata/multiline?req=%7B%22time%22%3A+%222024-12-01+2025-03-17%22%2C+%22resolution%22%3A+%22DAY%22%2C+%22locale%22%3A+%22ko%22%2C+%22comparisonItem%22%3A+%5B%7B%22geo%22%3A+%7B%22country%22%3A+%22KR%22%7D%2C+%22complexKeywordsRestriction%22%3A+%7B%22keyword%22%3A+%5B%7B%22type%22%3A+%22BROAD%22%2C+%22value%22%3A+%22%5Cuae40%5Cuacbd%5Cuc218%22%7D%5D%7D%7D%5D%2C+%22requestOptions%22%3A+%7B%22property%22%3A+%22%22%2C+%22backend%22%3A+%22IZG%22%2C+%22category%22%3A+0%7D%2C+%22userConfig%22%3A+%7B%22userType%22%3A+%22USER_TYPE_SCRAPER%22%7D%7D&token=APP6_UEAAAAAZ9o0yA9B1iLv25glt0jcIcZ7QloGojcB&tz=540 (Caused by ResponseError('too many 429 error responses'))

During handling of the above exception, another exception occurred:

Traceback (most recent call last):
  File "/home/airflow/.local/lib/python3.12/site-packages/airflow/models/taskinstance.py", line 768, in _execute_task
    result = _execute_callable(context=context, **execute_callable_kwargs)
             ^^^^^^^^^^^^^^^^^^^^^^^^^^^^^^^^^^^^^^^^^^^^^^^^^^^^^^^^^^^^^
  File "/home/airflow/.local/lib/python3.12/site-packages/airflow/models/taskinstance.py", line 734, in _execute_callable
    return ExecutionCallableRunner(
           ^^^^^^^^^^^^^^^^^^^^^^^^
  File "/home/airflow/.local/lib/python3.12/site-packages/airflow/utils/operator_helpers.py", line 252, in run
    return self.func(*args, **kwargs)
           ^^^^^^^^^^^^^^^^^^^^^^^^^^
  File "/home/airflow/.local/lib/python3.12/site-packages/airflow/models/baseoperator.py", line 424, in wrapper
    return func(self, *args, **kwargs)
           ^^^^^^^^^^^^^^^^^^^^^^^^^^^
  File "/home/airflow/.local/lib/python3.12/site-packages/airflow/operators/python.py", line 238, in execute
    return_value = self.execute_callable()
                   ^^^^^^^^^^^^^^^^^^^^^^^
  File "/home/airflow/.local/lib/python3.12/site-packages/airflow/operators/python.py", line 256, in execute_callable
    return runner.run(*self.op_args, **self.op_kwargs)
           ^^^^^^^^^^^^^^^^^^^^^^^^^^^^^^^^^^^^^^^^^^^
  File "/home/airflow/.local/lib/python3.12/site-packages/airflow/utils/operator_helpers.py", line 252, in run
    return self.func(*args, **kwargs)
           ^^^^^^^^^^^^^^^^^^^^^^^^^^
  File "/opt/airflow/plugins/scripts/extract/trend_extract.py", line 49, in extract_trend_data
    df = pytrends.interest_over_time()
         ^^^^^^^^^^^^^^^^^^^^^^^^^^^^^
  File "/home/airflow/.local/lib/python3.12/site-packages/pytrends/request.py", line 232, in interest_over_time
    req_json = self._get_data(
               ^^^^^^^^^^^^^^^
  File "/home/airflow/.local/lib/python3.12/site-packages/pytrends/request.py", line 140, in _get_data
    response = s.get(url, timeout=self.timeout, cookies=self.cookies,
               ^^^^^^^^^^^^^^^^^^^^^^^^^^^^^^^^^^^^^^^^^^^^^^^^^^^^^^
  File "/home/airflow/.local/lib/python3.12/site-packages/requests/sessions.py", line 602, in get
    return self.request("GET", url, **kwargs)
           ^^^^^^^^^^^^^^^^^^^^^^^^^^^^^^^^^^
  File "/home/airflow/.local/lib/python3.12/site-packages/requests/sessions.py", line 589, in request
    resp = self.send(prep, **send_kwargs)
           ^^^^^^^^^^^^^^^^^^^^^^^^^^^^^^
  File "/home/airflow/.local/lib/python3.12/site-packages/requests/sessions.py", line 703, in send
    r = adapter.send(request, **kwargs)
        ^^^^^^^^^^^^^^^^^^^^^^^^^^^^^^^
  File "/home/airflow/.local/lib/python3.12/site-packages/requests/adapters.py", line 691, in send
    raise RetryError(e, request=request)
requests.exceptions.RetryError: HTTPSConnectionPool(host='trends.google.com', port=443): Max retries exceeded with url: /trends/api/widgetdata/multiline?req=%7B%22time%22%3A+%222024-12-01+2025-03-17%22%2C+%22resolution%22%3A+%22DAY%22%2C+%22locale%22%3A+%22ko%22%2C+%22comparisonItem%22%3A+%5B%7B%22geo%22%3A+%7B%22country%22%3A+%22KR%22%7D%2C+%22complexKeywordsRestriction%22%3A+%7B%22keyword%22%3A+%5B%7B%22type%22%3A+%22BROAD%22%2C+%22value%22%3A+%22%5Cuae40%5Cuacbd%5Cuc218%22%7D%5D%7D%7D%5D%2C+%22requestOptions%22%3A+%7B%22property%22%3A+%22%22%2C+%22backend%22%3A+%22IZG%22%2C+%22category%22%3A+0%7D%2C+%22userConfig%22%3A+%7B%22userType%22%3A+%22USER_TYPE_SCRAPER%22%7D%7D&token=APP6_UEAAAAAZ9o0yA9B1iLv25glt0jcIcZ7QloGojcB&tz=540 (Caused by ResponseError('too many 429 error responses'))
[2025-03-18T03:09:25.709+0000] {logging_mixin.py:190} INFO - Task instance in failure state
[2025-03-18T03:09:25.710+0000] {logging_mixin.py:190} INFO - Task start:2025-03-18 03:06:47.674331+00:00 end:2025-03-18 03:09:25.709350+00:00 duration:158.035019
[2025-03-18T03:09:25.710+0000] {logging_mixin.py:190} INFO - Task:<Task(PythonOperator): extract> dag:<DAG: trend_dag> dagrun:<DagRun trend_dag @ 2025-03-18 02:59:47.095990+00:00: manual__2025-03-18T02:59:47.095990+00:00, state:running, queued_at: 2025-03-18 02:59:47.106780+00:00. externally triggered: True>
[2025-03-18T03:09:25.710+0000] {logging_mixin.py:190} INFO - Failure caused by HTTPSConnectionPool(host='trends.google.com', port=443): Max retries exceeded with url: /trends/api/widgetdata/multiline?req=%7B%22time%22%3A+%222024-12-01+2025-03-17%22%2C+%22resolution%22%3A+%22DAY%22%2C+%22locale%22%3A+%22ko%22%2C+%22comparisonItem%22%3A+%5B%7B%22geo%22%3A+%7B%22country%22%3A+%22KR%22%7D%2C+%22complexKeywordsRestriction%22%3A+%7B%22keyword%22%3A+%5B%7B%22type%22%3A+%22BROAD%22%2C+%22value%22%3A+%22%5Cuae40%5Cuacbd%5Cuc218%22%7D%5D%7D%7D%5D%2C+%22requestOptions%22%3A+%7B%22property%22%3A+%22%22%2C+%22backend%22%3A+%22IZG%22%2C+%22category%22%3A+0%7D%2C+%22userConfig%22%3A+%7B%22userType%22%3A+%22USER_TYPE_SCRAPER%22%7D%7D&token=APP6_UEAAAAAZ9o0yA9B1iLv25glt0jcIcZ7QloGojcB&tz=540 (Caused by ResponseError('too many 429 error responses'))
[2025-03-18T03:09:25.710+0000] {taskinstance.py:1226} INFO - Marking task as FAILED. dag_id=trend_dag, task_id=extract, run_id=manual__2025-03-18T02:59:47.095990+00:00, execution_date=20250318T025947, start_date=20250318T030647, end_date=20250318T030925
[2025-03-18T03:09:25.728+0000] {taskinstance.py:341} INFO - ::group::Post task execution logs
[2025-03-18T03:09:25.729+0000] {standard_task_runner.py:124} ERROR - Failed to execute job 290 for task extract (HTTPSConnectionPool(host='trends.google.com', port=443): Max retries exceeded with url: /trends/api/widgetdata/multiline?req=%7B%22time%22%3A+%222024-12-01+2025-03-17%22%2C+%22resolution%22%3A+%22DAY%22%2C+%22locale%22%3A+%22ko%22%2C+%22comparisonItem%22%3A+%5B%7B%22geo%22%3A+%7B%22country%22%3A+%22KR%22%7D%2C+%22complexKeywordsRestriction%22%3A+%7B%22keyword%22%3A+%5B%7B%22type%22%3A+%22BROAD%22%2C+%22value%22%3A+%22%5Cuae40%5Cuacbd%5Cuc218%22%7D%5D%7D%7D%5D%2C+%22requestOptions%22%3A+%7B%22property%22%3A+%22%22%2C+%22backend%22%3A+%22IZG%22%2C+%22category%22%3A+0%7D%2C+%22userConfig%22%3A+%7B%22userType%22%3A+%22USER_TYPE_SCRAPER%22%7D%7D&token=APP6_UEAAAAAZ9o0yA9B1iLv25glt0jcIcZ7QloGojcB&tz=540 (Caused by ResponseError('too many 429 error responses')); 113)
Traceback (most recent call last):
  File "/home/airflow/.local/lib/python3.12/site-packages/requests/adapters.py", line 667, in send
    resp = conn.urlopen(
           ^^^^^^^^^^^^^
  File "/home/airflow/.local/lib/python3.12/site-packages/urllib3/connectionpool.py", line 889, in urlopen
    return self.urlopen(
           ^^^^^^^^^^^^^
  File "/home/airflow/.local/lib/python3.12/site-packages/urllib3/connectionpool.py", line 889, in urlopen
    return self.urlopen(
           ^^^^^^^^^^^^^
  File "/home/airflow/.local/lib/python3.12/site-packages/urllib3/connectionpool.py", line 889, in urlopen
    return self.urlopen(
           ^^^^^^^^^^^^^
  [Previous line repeated 1 more time]
  File "/home/airflow/.local/lib/python3.12/site-packages/urllib3/connectionpool.py", line 826, in urlopen
    return self.urlopen(
           ^^^^^^^^^^^^^
  File "/home/airflow/.local/lib/python3.12/site-packages/urllib3/connectionpool.py", line 879, in urlopen
    retries = retries.increment(method, url, response=response, _pool=self)
              ^^^^^^^^^^^^^^^^^^^^^^^^^^^^^^^^^^^^^^^^^^^^^^^^^^^^^^^^^^^^^
  File "/home/airflow/.local/lib/python3.12/site-packages/urllib3/util/retry.py", line 592, in increment
    raise MaxRetryError(_pool, url, error or ResponseError(cause))
urllib3.exceptions.MaxRetryError: HTTPSConnectionPool(host='trends.google.com', port=443): Max retries exceeded with url: /trends/api/widgetdata/multiline?req=%7B%22time%22%3A+%222024-12-01+2025-03-17%22%2C+%22resolution%22%3A+%22DAY%22%2C+%22locale%22%3A+%22ko%22%2C+%22comparisonItem%22%3A+%5B%7B%22geo%22%3A+%7B%22country%22%3A+%22KR%22%7D%2C+%22complexKeywordsRestriction%22%3A+%7B%22keyword%22%3A+%5B%7B%22type%22%3A+%22BROAD%22%2C+%22value%22%3A+%22%5Cuae40%5Cuacbd%5Cuc218%22%7D%5D%7D%7D%5D%2C+%22requestOptions%22%3A+%7B%22property%22%3A+%22%22%2C+%22backend%22%3A+%22IZG%22%2C+%22category%22%3A+0%7D%2C+%22userConfig%22%3A+%7B%22userType%22%3A+%22USER_TYPE_SCRAPER%22%7D%7D&token=APP6_UEAAAAAZ9o0yA9B1iLv25glt0jcIcZ7QloGojcB&tz=540 (Caused by ResponseError('too many 429 error responses'))

During handling of the above exception, another exception occurred:

Traceback (most recent call last):
  File "/home/airflow/.local/lib/python3.12/site-packages/airflow/task/task_runner/standard_task_runner.py", line 117, in _start_by_fork
    ret = args.func(args, dag=self.dag)
          ^^^^^^^^^^^^^^^^^^^^^^^^^^^^^
  File "/home/airflow/.local/lib/python3.12/site-packages/airflow/cli/cli_config.py", line 49, in command
    return func(*args, **kwargs)
           ^^^^^^^^^^^^^^^^^^^^^
  File "/home/airflow/.local/lib/python3.12/site-packages/airflow/utils/cli.py", line 116, in wrapper
    return f(*args, **kwargs)
           ^^^^^^^^^^^^^^^^^^
  File "/home/airflow/.local/lib/python3.12/site-packages/airflow/cli/commands/task_command.py", line 483, in task_run
    task_return_code = _run_task_by_selected_method(args, _dag, ti)
                       ^^^^^^^^^^^^^^^^^^^^^^^^^^^^^^^^^^^^^^^^^^^^
  File "/home/airflow/.local/lib/python3.12/site-packages/airflow/cli/commands/task_command.py", line 256, in _run_task_by_selected_method
    return _run_raw_task(args, ti)
           ^^^^^^^^^^^^^^^^^^^^^^^
  File "/home/airflow/.local/lib/python3.12/site-packages/airflow/cli/commands/task_command.py", line 341, in _run_raw_task
    return ti._run_raw_task(
           ^^^^^^^^^^^^^^^^^
  File "/home/airflow/.local/lib/python3.12/site-packages/airflow/utils/session.py", line 97, in wrapper
    return func(*args, session=session, **kwargs)
           ^^^^^^^^^^^^^^^^^^^^^^^^^^^^^^^^^^^^^^
  File "/home/airflow/.local/lib/python3.12/site-packages/airflow/models/taskinstance.py", line 3006, in _run_raw_task
    return _run_raw_task(
           ^^^^^^^^^^^^^^
  File "/home/airflow/.local/lib/python3.12/site-packages/airflow/models/taskinstance.py", line 274, in _run_raw_task
    TaskInstance._execute_task_with_callbacks(
  File "/home/airflow/.local/lib/python3.12/site-packages/airflow/models/taskinstance.py", line 3161, in _execute_task_with_callbacks
    result = self._execute_task(context, task_orig)
             ^^^^^^^^^^^^^^^^^^^^^^^^^^^^^^^^^^^^^^
  File "/home/airflow/.local/lib/python3.12/site-packages/airflow/models/taskinstance.py", line 3185, in _execute_task
    return _execute_task(self, context, task_orig)
           ^^^^^^^^^^^^^^^^^^^^^^^^^^^^^^^^^^^^^^^
  File "/home/airflow/.local/lib/python3.12/site-packages/airflow/models/taskinstance.py", line 768, in _execute_task
    result = _execute_callable(context=context, **execute_callable_kwargs)
             ^^^^^^^^^^^^^^^^^^^^^^^^^^^^^^^^^^^^^^^^^^^^^^^^^^^^^^^^^^^^^
  File "/home/airflow/.local/lib/python3.12/site-packages/airflow/models/taskinstance.py", line 734, in _execute_callable
    return ExecutionCallableRunner(
           ^^^^^^^^^^^^^^^^^^^^^^^^
  File "/home/airflow/.local/lib/python3.12/site-packages/airflow/utils/operator_helpers.py", line 252, in run
    return self.func(*args, **kwargs)
           ^^^^^^^^^^^^^^^^^^^^^^^^^^
  File "/home/airflow/.local/lib/python3.12/site-packages/airflow/models/baseoperator.py", line 424, in wrapper
    return func(self, *args, **kwargs)
           ^^^^^^^^^^^^^^^^^^^^^^^^^^^
  File "/home/airflow/.local/lib/python3.12/site-packages/airflow/operators/python.py", line 238, in execute
    return_value = self.execute_callable()
                   ^^^^^^^^^^^^^^^^^^^^^^^
  File "/home/airflow/.local/lib/python3.12/site-packages/airflow/operators/python.py", line 256, in execute_callable
    return runner.run(*self.op_args, **self.op_kwargs)
           ^^^^^^^^^^^^^^^^^^^^^^^^^^^^^^^^^^^^^^^^^^^
  File "/home/airflow/.local/lib/python3.12/site-packages/airflow/utils/operator_helpers.py", line 252, in run
    return self.func(*args, **kwargs)
           ^^^^^^^^^^^^^^^^^^^^^^^^^^
  File "/opt/airflow/plugins/scripts/extract/trend_extract.py", line 49, in extract_trend_data
    df = pytrends.interest_over_time()
         ^^^^^^^^^^^^^^^^^^^^^^^^^^^^^
  File "/home/airflow/.local/lib/python3.12/site-packages/pytrends/request.py", line 232, in interest_over_time
    req_json = self._get_data(
               ^^^^^^^^^^^^^^^
  File "/home/airflow/.local/lib/python3.12/site-packages/pytrends/request.py", line 140, in _get_data
    response = s.get(url, timeout=self.timeout, cookies=self.cookies,
               ^^^^^^^^^^^^^^^^^^^^^^^^^^^^^^^^^^^^^^^^^^^^^^^^^^^^^^
  File "/home/airflow/.local/lib/python3.12/site-packages/requests/sessions.py", line 602, in get
    return self.request("GET", url, **kwargs)
           ^^^^^^^^^^^^^^^^^^^^^^^^^^^^^^^^^^
  File "/home/airflow/.local/lib/python3.12/site-packages/requests/sessions.py", line 589, in request
    resp = self.send(prep, **send_kwargs)
           ^^^^^^^^^^^^^^^^^^^^^^^^^^^^^^
  File "/home/airflow/.local/lib/python3.12/site-packages/requests/sessions.py", line 703, in send
    r = adapter.send(request, **kwargs)
        ^^^^^^^^^^^^^^^^^^^^^^^^^^^^^^^
  File "/home/airflow/.local/lib/python3.12/site-packages/requests/adapters.py", line 691, in send
    raise RetryError(e, request=request)
requests.exceptions.RetryError: HTTPSConnectionPool(host='trends.google.com', port=443): Max retries exceeded with url: /trends/api/widgetdata/multiline?req=%7B%22time%22%3A+%222024-12-01+2025-03-17%22%2C+%22resolution%22%3A+%22DAY%22%2C+%22locale%22%3A+%22ko%22%2C+%22comparisonItem%22%3A+%5B%7B%22geo%22%3A+%7B%22country%22%3A+%22KR%22%7D%2C+%22complexKeywordsRestriction%22%3A+%7B%22keyword%22%3A+%5B%7B%22type%22%3A+%22BROAD%22%2C+%22value%22%3A+%22%5Cuae40%5Cuacbd%5Cuc218%22%7D%5D%7D%7D%5D%2C+%22requestOptions%22%3A+%7B%22property%22%3A+%22%22%2C+%22backend%22%3A+%22IZG%22%2C+%22category%22%3A+0%7D%2C+%22userConfig%22%3A+%7B%22userType%22%3A+%22USER_TYPE_SCRAPER%22%7D%7D&token=APP6_UEAAAAAZ9o0yA9B1iLv25glt0jcIcZ7QloGojcB&tz=540 (Caused by ResponseError('too many 429 error responses'))
[2025-03-18T03:09:25.778+0000] {local_task_job_runner.py:266} INFO - Task exited with return code 1
[2025-03-18T03:09:25.792+0000] {taskinstance.py:3901} INFO - 0 downstream tasks scheduled from follow-on schedule check
[2025-03-18T03:09:25.794+0000] {local_task_job_runner.py:245} INFO - ::endgroup::
